Workbook

Sheet SL INT
A1: TANGGAL | B1: YEAR | C1: MONTH | D1: LOP | E1: TEUS | F1: %
A2: 01/2022 | B2: =YEAR(A2) -> 2022 | C2: =MONTH(A2) -> 1 | D2: CMA | E2: 12085 | F2: =(E290-E2)/E290 -> 0.14641899
A3: 01/2022 | B3: =YEAR(A3) -> 2022 | C3: =MONTH(A3) -> 1 | D3: EMC | E3: 12494 | F3: =(E291-E3)/E291 -> 0.081391074
A4: 01/2022 | B4: =YEAR(A4) -> 2022 | C4: =MONTH(A4) -> 1 | D4: MSK | E4: 14065 | F4: =(E292-E4)/E292 -> -0.42228739
A5: 01/2022 | B5: =YEAR(A5) -> 2022 | C5: =MONTH(A5) -> 1 | D5: MSC | E5: 11120 | F5: =(E293-E5)/E293 -> -0.034033848
A6: 01/2022 | B6: =YEAR(A6) -> 2022 | C6: =MONTH(A6) -> 1 | D6: ONE | E6: 12015 | F6: =(E294-E6)/E294 -> -0.13434668
A7: 01/2022 | B7: =YEAR(A7) -> 2022 | C7: =MONTH(A7) -> 1 | D7: WHL | E7: 6221 | F7: =(E295-E7)/E295 -> 0.12157583
A8: 01/2022 | B8: =YEAR(A8) -> 2022 | C8: =MONTH(A8) -> 1 | D8: COSCO | E8: 10768 | F8: =(E296-E8)/E296 -> -0.5480161
A9: 01/2022 | B9: =YEAR(A9) -> 2022 | C9: =MONTH(A9) -> 1 | D9: OOCL | E9: 5100 | F9: =(E297-E9)/E297 -> 0.043690231
A10: 01/2022 | B10: =YEAR(A10) -> 2022 | C10: =MONTH(A10) -> 1 | D10: RCL | E10: 618 | F10: =(E298-E10)/E298 -> 0.81791397
A11: 01/2022 | B11: =YEAR(A11) -> 2022 | C11: =MONTH(A11) -> 1 | D11: HAPAG | E11: 0 | F11: 0
A12: 01/2022 | B12: =YEAR(A12) -> 2022 | C12: =MONTH(A12) -> 1 | D12: SITC | E12: 4174 | F12: =(E300-E12)/E300 -> -0.23967924
A13: 01/2022 | B13: =YEAR(A13) -> 2022 | C13: =MONTH(A13) -> 1 | D13: KMTC | E13: 3316 | F13: =(E301-E13)/E301 -> -0.97852029
A14: 01/2022 | B14: =YEAR(A14) -> 2022 | C14: =MONTH(A14) -> 1 | D14: YML | E14: 2275 | F14: =(E302-E14)/E302 -> 0.1296863
A15: 01/2022 | B15: =YEAR(A15) -> 2022 | C15: =MONTH(A15) -> 1 | D15: GSL | E15: 1186 | F15: =(E303-E15)/E303 -> 0.22635356
A16: 01/2022 | B16: =YEAR(A16) -> 2022 | C16: =MONTH(A16) -> 1 | D16: OTHERS | E16: 2347 | F16: =(E304-E16)/E304 -> 0.27561728
A17: 01/2022 | B17: =YEAR(A17) -> 2022 | C17: =MONTH(A17) -> 1 | D17: SSL | E17: 2157 | F17: =(E305-E17)/E305 -> -1.5678571
A18: 01/2022 | B18: =YEAR(A18) -> 2022 | C18: =MONTH(A18) -> 1 | D18: PIL | E18: 2262 | F18: =(E306-E18)/E306 -> -1.2987805
A19: 01/2022 | B19: =YEAR(A19) -> 2022 | C19: =MONTH(A19) -> 1 | D19: ANL | E19: 0 | F19: 0
A20: 01/2022 | B20: =YEAR(A20) -> 2022 | C20: =MONTH(A20) -> 1 | D20: HMM | E20: 1559 | F20: =(E308-E20)/E308 -> -2.6425234
A21: 01/2022 | B21: =YEAR(A21) -> 2022 | C21: =MONTH(A21) -> 1 | D21: XCL | E21: 1542 | F21: =(E309-E21)/E309 -> -6.7487437
A22: 01/2022 | B22: =YEAR(A22) -> 2022 | C22: =MONTH(A22) -> 1 | D22: MELL | E22: 255 | F22: 0
A23: 01/2022 | B23: =YEAR(A23) -> 2022 | C23: =MONTH(A23) -> 1 | D23: BEN | E23: 0 | F23: 0
A24: 01/2022 | B24: =YEAR(A24) -> 2022 | C24: =MONTH(A24) -> 1 | D24: KRL | E24: 0 | F24: 0
A25: 44593 | B25: =YEAR(A25) -> 2022 | C25: =MONTH(A25) -> 2 | D25: KSL | E25: 0 | F25: 0
A26: 44594 | B26: =YEAR(A26) -> 2022 | C26: =MONTH(A26) -> 2 | D26: CMA | E26: 25419 | F26: =(E314-E26)/E314 -> 0.028956718
A27: 44595 | B27: =YEAR(A27) -> 2022 | C27: =MONTH(A27) -> 2 | D27: EMC | E27: 26036 | F27: =(E315-E27)/E315 -> 0.012291351
A28: 44596 | B28: =YEAR(A28) -> 2022 | C28: =MONTH(A28) -> 2 | D28: MSK | E28: 27297 | F28: =(E316-E28)/E316 -> -0.17240046
A29: 44597 | B29: =YEAR(A29) -> 2022 | C29: =MONTH(A29) -> 2 | D29: MSC | E29: 22751 | F29: =(E317-E29)/E317 -> -0.20305642
A30: 44598 | B30: =YEAR(A30) -> 2022 | C30: =MONTH(A30) -> 2 | D30: ONE | E30: 21359 | F30: =(E318-E30)/E318 -> -0.072885272
A31: 44599 | B31: =YEAR(A31) -> 2022 | C31: =MONTH(A31) -> 2 | D31: WHL | E31: 13712 | F31: =(E319-E31)/E319 -> 0.022874653
A32: 44600 | B32: =YEAR(A32) -> 2022 | C32: =MONTH(A32) -> 2 | D32: COSCO | E32: 23893 | F32: =(E320-E32)/E320 -> -0.67964851
A33: 44601 | B33: =YEAR(A33) -> 2022 | C33: =MONTH(A33) -> 2 | D33: OOCL | E33: 9161 | F33: =(E321-E33)/E321 -> 0.1717747
A34: 44602 | B34: =YEAR(A34) -> 2022 | C34: =MONTH(A34) -> 2 | D34: RCL | E34: 1061 | F34: =(E322-E34)/E322 -> 0.84415394
A35: 44603 | B35: =YEAR(A35) -> 2022 | C35: =MONTH(A35) -> 2 | D35: HAPAG | E35: 0 | F35: 0
A36: 44604 | B36: =YEAR(A36) -> 2022 | C36: =MONTH(A36) -> 2 | D36: SITC | E36: 7321 | F36: =(E324-E36)/E324 -> -0.23311437
A37: 44605 | B37: =YEAR(A37) -> 2022 | C37: =MONTH(A37) -> 2 | D37: KMTC | E37: 5047 | F37: =(E325-E37)/E325 -> -0.48005865
A38: 44606 | B38: =YEAR(A38) -> 2022 | C38: =MONTH(A38) -> 2 | D38: YML | E38: 4176 | F38: =(E326-E38)/E326 -> 0.2141513
A39: 44607 | B39: =YEAR(A39) -> 2022 | C39: =MONTH(A39) -> 2 | D39: GSL | E39: 2395 | F39: =(E327-E39)/E327 -> 0.25851393
A40: 44608 | B40: =YEAR(A40) -> 2022 | C40: =MONTH(A40) -> 2 | D40: OTHERS | E40: 4257 | F40: =(E328-E40)/E328 -> 0.32126913
...

Sheet BOX. OPR PIVOT
A1: TAHUN | B1: MONTH | C1: DESCRIPTION | D1: UNIT | E1: 2022 ACTUAL | F1: 2022 BUDGET | G1: 2022 ACTUAL VS 2022 BUDGET | H1: 2023 ACTUAL | I1: 2023 BUDGET | J1: 2023 ACTUAL VS 2023 BUDGET | K1: 2024 ACTUAL | L1: 2024 BUDGET | M1: 2024 ACTUAL VS 2024 ACTUAL BUDGET | N1: 2025 ACTUAL | O1: 2025 BUDGET | P1: 2025 ACTUAL VS 2025 BUDGET | Q1: 2026 ACTUAL | R1: 2026 BUDGET | S1: 2026 ACTUAL VS 2026 BUDGET
A2: 44562 | B2: =MONTH(A2) -> 1 | C2: Kumulatif International | D2: TEUs | E2: 95784 | F2: 96409 | G2: -0.0065 | H2: 98611 | I2: 104854 | J2: -0.0595 | K2: 119547 | L2: 105043 | M2: 0.1381 | N2: 114919 | O2: 111747 | P2: =(N2/O2)-100% -> 0.02838555 | Q2: 110561 | R2: 116604 | S2: -0.0518
A3: 44593 | B3: =MONTH(A2) -> 1 | C3: International | D3: TEUs | E3: 95784 | F3: 96409 | G3: -0.0065 | H3: 98611 | I3: 104854 | J3: -0.0595 | K3: 119547 | L3: 105043 | M3: 0.1381 | N3: 114919 | O3: 111747 | P3: =(N3/O3)-100% -> 0.02838555 | Q3: 7309 | R3: 7196 | S3: 0.0157
A4: 44621 | B4: =MONTH(A2) -> 1 | C4: Kumulatif Domestic | D4: TEUs | E4: 6924 | F4: 8229 | G4: -0.1586 | H4: 4717 | I4: 7774 | J4: -0.3932 | K4: 10116 | L4: 5741 | M4: 0.7621 | N4: 5938 | O4: 7196 | P4: =(N4/O4)-100% -> -0.17481934
A5: 44652 | B5: =MONTH(A2) -> 1 | C5: Domestic | D5: TEUs | E5: 6924 | F5: 8229 | G5: -0.1586 | H5: 4717 | I5: 7774 | J5: -0.3932 | K5: 10116 | L5: 5741 | M5: 0.7621 | N5: 5938 | O5: 7196 | P5: =(N5/O5)-100% -> -0.17481934
A6: 44682 | B6: =MONTH(A3) -> 2 | C6: Kumulatif International | D6: TEUs | E6: =E7+E2 -> 212051 | F6: =F7+F2 -> 210756 | G6: =(E6/F6)-100% -> 0.0061445463 | H6: =H7+H2 -> 195430 | I6: =I7+I2 -> 207224 | J6: =(H6/I6)-100% -> -0.056914257 | K6: =K7+K2 -> 234797 | L6: =L7+L2 -> 197969 | M6: =(K6/L6)-100% -> 0.18602913 | N6: 232679 | O6: 228099 | P6: =(N6/O6)-100% -> 0.020079001
A7: 44713 | B7: =MONTH(A3) -> 2 | C7: International | D7: TEUs | E7: 116267 | F7: 114347 | G7: 0.0168 | H7: 96819 | I7: 102370 | J7: -0.0542 | K7: 115250 | L7: 92926 | M7: 0.2402 | N7: 117761 | O7: 116352 | P7: =(N7/O7)-100% -> 0.012109805
A8: 44743 | B8: =MONTH(A3) -> 2 | C8: Kumulatif Domestic | D8: TEUs | E8: =E9+E4 -> 14192 | F8: =F9+F4 -> 17028 | G8: =(E8/F8)-100% -> -0.16654921 | H8: =H9+H4 -> 8988 | I8: =I9+I4 -> 16089 | J8: =(H8/I8)-100% -> -0.44135745 | K8: =K9+K4 -> 18144 | L8: =L9+L4 -> 10820 | M8: =(K8/L8)-100% -> 0.67689464 | N8: 13651 | O8: 14329 | P8: =(N8/O8)-100% -> -0.047316631
A9: 44774 | B9: =MONTH(A3) -> 2 | C9: Domestic | D9: TEUs | E9: 7268 | F9: 8799 | G9: -0.174 | H9: 4271 | I9: 8315 | J9: -0.4863 | K9: 8028 | L9: 5079 | M9: 0.5806 | N9: 7713 | O9: 7133 | P9: =(N9/O9)-100% -> 0.081312211
A10: 44805 | B10: =MONTH(A4) -> 3 | C10: Kumulatif International | D10: TEUs | E10: =E11+E6 -> 311260 | F10: =F11+F6 -> 337015 | G10: =F10/E10-100% -> 0.082744329 | H10: =H11+H6 -> 311660 | I10: =I11+I6 -> 314431 | J10: =I10/H10-100% -> 0.0088910993 | K10: =K11+K6 -> 359917 | L10: =L11+L6 -> 298292 | M10: =L10/K10-100% -> -0.17122003 | N10: 361052 | O10: 353507 | P10: =(N10/O10)-100% -> 0.021343283
A11: 44835 | B11: =MONTH(A4) -> 3 | C11: International | D11: TEUs | E11: 99209 | F11: 126259 | G11: -0.2142 | H11: 116230 | I11: 107207 | J11: 0.0842 | K11: 125120 | L11: 100323 | M11: 0.2472 | N11: 128373 | O11: 125408 | P11: =(N11/O11)-100% -> 0.02364283
A12: 44866 | B12: =MONTH(A4) -> 3 | C12: Kumulatif Domestic | D12: TEUs | E12: =E13+E8 -> 21013 | F12: =F13+F8 -> 27067 | G12: =F12/E12-100% -> 0.28810736 | H12: =H13+H8 -> 16478 | I12: =I13+I8 -> 25574 | J12: =I12/H12-100% -> 0.55200874 | K12: =K13+K8 -> 26791 | L12: =L13+L8 -> 16008 | M12: =L12/K12-100% -> -0.40248591 | N12: 19437 | O12: 23176 | P12: =(N12/O12)-100% -> -0.16133069
A13: 44896 | B13: =MONTH(A4) -> 3 | C13: Domestic | D13: TEUs | E13: 6821 | F13: 10039 | G13: -0.3205 | H13: 7490 | I13: 9485 | J13: -0.2104 | K13: 8647 | L13: 5188 | M13: 0.6667 | N13: 5786 | O13: 8847 | P13: =(N13/O13)-100% -> -0.34599299
B14: =MONTH(A5) -> 4 | C14: Kumulatif International | D14: TEUs | E14: =E15+E10 -> 416779 | F14: =F15+F10 -> 460293 | G14: =(E14/F14)-100% -> -0.094535437 | H14: =H15+H10 -> 413882 | I14: =I15+I10 -> 418762 | J14: =(H14/I14)-100% -> -0.011653397 | K14: =K15+K10 -> 360018.59 | L14: =L15+L10 -> 298395.18 | M14: =(K14/L14)-100% -> 0.20651611 | N14: 476008 | O14: 474617 | P14: =(N14/O14)-100% -> 0.0029307842
B15: =MONTH(A5) -> 4 | C15: International | D15: TEUs | E15: 105519 | F15: 123278 | G15: -0.1441 | H15: 102222 | I15: 104331 | J15: -0.0202 | K15: 101.59 | L15: 103.179 | M15: -0.0154 | N15: 114955 | O15: 121110 | P15: =(N15/O15)-100% -> -0.050821567
B16: =MONTH(A5) -> 4 | C16: Kumulatif Domestic | D16: TEUs | E16: =E17+E12 -> 28139 | F16: =F17+F12 -> 35160 | G16: =(E16/F16)-100% -> -0.19968714 | H16: =H17+H12 -> 20994 | I16: =I17+I12 -> 33223 | J16: =(H16/I16)-100% -> -0.36808837 | K16: =K17+K12 -> 26794.697 | L16: =L17+L12 -> 16013.639 | M16: =(K16/L16)-100% -> 0.67324223 | N16: 22719 | O16: 30373 | P16: =(N16/O16)-100% -> -0.25200013
B17: =MONTH(A5) -> 4 | C17: Domestic | D17: TEUs | E17: 7126 | F17: 8093 | G17: -0.1195 | H17: 4516 | I17: 7649 | J17: -0.0202 | K17: 3.697 | L17: 5.639 | M17: -0.3444 | N17: 3282 | O17: 7197 | P17: =(N17/O17)-100% -> -0.54397666
B18: =MONTH(A6) -> 5 | C18: Kumulatif International | D18: TEUs | E18: =E19+E14 -> 516117 | F18: =F19+F14 -> 567857 | G18: =(E18/F18)-100% -> -0.091114488 | H18: =H19+H14 -> 535443 | I18: =I19+I14 -> 527669 | J18: =(H18/I18)-100% -> 0.014732721 | K18: =K19+K14 -> 492047.59 | L18: =L19+L14 -> 409164.18 | M18: =(K18/L18)-100% -> 0.20256761 | N18: 603880 | O18: 603249 | P18: =(N18/O18)-100% -> 0.0010460026
B19: =MONTH(A6) -> 5 | C19: International | D19: TEUs | E19: 99338 | F19: 107564 | G19: -0.0765 | H19: 121561 | I19: 108907 | J19: 0.1162 | K19: 132029 | L19: 110769 | M19: 0.1919 | N19: 127873 | O19: 128632 | P19: =(N19/O19)-100% -> -0.0059005535
B20: =MONTH(A6) -> 5 | C20: Kumulatif Domestic | D20: TEUs | E20: =E21+E16 -> 35138 | F20: =F21+F16 -> 40384 | G20: =(E20/F20)-100% -> -0.12990293 | H20: =H21+H16 -> 24636 | I20: =I21+I16 -> 38158 | J20: =(H20/I20)-100% -> -0.35436868 | K20: =K21+K16 -> 30839.697 | L20: =L21+L16 -> 22067.639 | M20: =(K20/L20)-100% -> 0.39750777 | N20: 28687 | O20: 36951 | P20: =(N20/O20)-100% -> -0.22364753
B21: =MONTH(A6) -> 5 | C21: Domestic | D21: TEUs | E21: 6999 | F21: 5224 | G21: 0.3398 | H21: 3642 | I21: 4935 | J21: -0.262 | K21: 4045 | L21: 6054 | M21: -0.3318 | N21: 5968 | O21: 6578 | P21: =(N21/O21)-100% -> -0.092733354
B22: =MONTH(A7) -> 6 | C22: Kumulatif International | D22: TEUs | E22: =E23+E18 -> 625946 | F22: =F23+F18 -> 684397 | G22: =(E22/F22)-100% -> -0.085405108 | H22: =H23+H18 -> 644771 | I22: =I23+I18 -> 636706 | J22: =(H22/I22)-100% -> 0.012666757 | K22: =K23+K18 -> 612060.59 | L22: =L23+L18 -> 521531.18 | M22: =(K22/L22)-100% -> 0.17358389 | N22: 734179 | O22: 730806 | P22: =(N22/O22)-100% -> 0.004615452
B23: =MONTH(A7) -> 6 | C23: International | D23: TEUs | E23: 109829 | F23: 116540 | G23: -0.0576 | H23: 109328 | I23: 109037 | J23: 0.0027 | K23: 120013 | L23: 112367 | M23: 0.068 | N23: 130299 | O23: 127557 | P23: =(N23/O23)-100% -> 0.021496272
B24: =MONTH(A7) -> 6 | C24: Kumulatif Domestic | D24: TEUs | E24: =E25+E20 -> 42298 | F24: =F25+F20 -> 45604 | G24: =(E24/F24)-100% -> -0.072493641 | H24: =H25+H20 -> 30120 | I24: =I25+I20 -> 43089 | J24: =(H24/I24)-100% -> -0.30098169 | K24: =K25+K20 -> 37643.697 | L24: =L25+L20 -> 28208.639 | M24: =(K24/L24)-100% -> 0.33447406 | N24: 34339 | O24: 44767 | P24: =(N24/O24)-100% -> -0.23293944
B25: =MONTH(A7) -> 6 | C25: Domestic | D25: TEUs | E25: 7160 | F25: 5220 | G25: 0.3716 | H25: 5484 | I25: 4931 | J25: 0.1121 | K25: 6804 | L25: 6141 | M25: 0.108 | N25: 5652 | O25: 7816 | P25: =(N25/O25)-100% -> -0.27686796
B26: =MONTH(A8) -> 7 | C26: Kumulatif International | D26: TEUs | E26: =E27+E22 -> 732329 | F26: =F27+F22 -> 792537 | G26: =(E26/F26)-100% -> -0.075968693 | H26: =H27+H22 -> 774871 | I26: =I27+I22 -> 746136 | J26: =(H26/I26)-100% -> 0.038511746 | K26: =K27+K22 -> 740980.59 | L26: =L27+L22 -> 635496.18 | M26: =(K26/L26)-100% -> 0.16598748 | N26: 867888 | O26: 866806 | P26: =(N26/O26)-100% -> 0.0012482609
B27: =MONTH(A8) -> 7 | C27: International | D27: TEUs | E27: 106383 | F27: 108140 | G27: -0.0162 | H27: 130100 | I27: 109430 | J27: 0.1889 | K27: 128920 | L27: 113965 | M27: 0.1312 | N27: 133709 | O27: 136000 | P27: =(N27/O27)-100% -> -0.016845588
B28: =MONTH(A8) -> 7 | C28: Kumulatif Domestic | D28: TEUs | E28: =E29+E24 -> 47798 | F28: =F29+F24 -> 51820 | G28: =(E28/F28)-100% -> -0.077614821 | H28: =H29+H24 -> 32584 | I28: =I29+I24 -> 48963 | J28: =(H28/I28)-100% -> -0.3345179 | K28: =K29+K24 -> 42981.697 | L28: =L29+L24 -> 34436.639 | M28: =(K28/L28)-100% -> 0.24813856 | N28: 40248 | O28: 49690 | P28: =(N28/O28)-100% -> -0.19001811
B29: =MONTH(A8) -> 7 | C29: Domestic | D29: TEUs | E29: 5500 | F29: 6216 | G29: -0.1152 | H29: 2464 | I29: 5874 | J29: -0.5805 | K29: 5338 | L29: 6228 | M29: -0.1429 | N29: 5909 | O29: 4923 | P29: =(N29/O29)-100% -> 0.20028438
B30: =MONTH(A9) -> 8 | C30: Kumulatif International | D30: TEUs | E30: =E31+E26 -> 857743 | F30: =F31+F26 -> 913249 | G30: =(E30/F30)-100% -> -0.060778605 | H30: =H31+H26 -> 889888 | I30: =I31+I26 -> 855958 | J30: =(H30/I30)-100% -> 0.039639795 | K30: =K31+K26 -> 876727.59 | L30: =L31+L26 -> 751059.18 | M30: =(K30/L30)-100% -> 0.16732158 | N30: 988526 | O30: 1005108 | P30: =(N30/O30)-100% -> -0.01649773
B31: =MONTH(A9) -> 8 | C31: International | D31: TEUs | E31: 125414 | F31: 120712 | G31: 0.039 | H31: 115017 | I31: 109822 | J31: 0.0473 | K31: 135747 | L31: 115563 | M31: 0.1747 | N31: 120637 | O31: 138302 | P31: =(N31/O31)-100% -> -0.12772773
B32: =MONTH(A9) -> 8 | C32: Kumulatif Domestic | D32: TEUs | E32: =E33+E28 -> 54527 | F32: =F33+F28 -> 57474 | G32: =(E32/F32)-100% -> -0.051275359 | H32: =H33+H28 -> 40315 | I32: =I33+I28 -> 54307 | J32: =(H32/I32)-100% -> -0.25764634 | K32: =K33+K28 -> 48905.697 | L32: =L33+L28 -> 40752.639 | M32: =(K32/L32)-100% -> 0.20006209 | N32: 44098 | O32: 58629 | P32: =(N32/O32)-100% -> -0.24784663
B33: =MONTH(A9) -> 8 | C33: Domestic | D33: TEUs | E33: 6729 | F33: 5654 | G33: 0.1901 | H33: 7731 | I33: 5344 | J33: 0.4467 | K33: 5924 | L33: 6316 | M33: -0.0621 | N33: 3850 | O33: 8939 | P33: =(N33/O33)-100% -> -0.56930305
B34: =MONTH(A10) -> 9 | C34: Kumulatif International | D34: TEUs | E34: =E35+E30 -> 955694 | F34: =F35+F30 -> 1018528 | G34: =(E34/F34)-100% -> -0.061690989 | H34: =H35+H30 -> 1009618 | I34: =I35+I30 -> 967989 | J34: =(H34/I34)-100% -> 0.043005654 | K34: =K35+K30 -> 1007075.6 | L34: =L35+L30 -> 868220.18 | M34: =(K34/L34)-100% -> 0.1599311 | N34: 1115827 | O34: 1130209 | P34: =(N34/O34)-100% -> -0.01272508
B35: =MONTH(A10) -> 9 | C35: International | D35: TEUs | E35: 97951 | F35: 105279 | G35: -0.0696 | H35: 119730 | I35: 112031 | J35: 0.0687 | K35: 130348 | L35: 117161 | M35: 0.1126 | N35: 127302 | O35: 125101 | P35: =(N35/O35)-100% -> 0.017593784
B36: =MONTH(A10) -> 9 | C36: Kumulatif Domestic | D36: TEUs | E36: =E37+E32 -> 58974 | F36: =F37+F32 -> 64904 | G36: =(E36/F36)-100% -> -0.091365709 | H36: =H37+H32 -> 47970 | I36: =I37+I32 -> 61330 | J36: =(H36/I36)-100% -> -0.21783793 | K36: =K37+K32 -> 54787.697 | L36: =L37+L32 -> 47155.639 | M36: =(K36/L36)-100% -> 0.16184826 | N36: 47883 | O36: 66110 | P36: =(N36/O36)-100% -> -0.27570715
B37: =MONTH(A10) -> 9 | C37: Domestic | D37: TEUs | E37: 4447 | F37: 7430 | G37: -0.4015 | H37: 7655 | I37: 7023 | J37: 0.09 | K37: 5882 | L37: 6403 | M37: -0.0814 | N37: 3785 | O37: 7481 | P37: =(N37/O37)-100% -> -0.4940516
B38: =MONTH(A11) -> 10 | C38: Kumulatif International | D38: TEUs | E38: =E39+E34 -> 1069456 | F38: =F39+F34 -> 1137223 | G38: =(E38/F38)-100% -> -0.059589896 | H38: =H39+H34 -> 1138338 | I38: =I39+I34 -> 1080949 | J38: =(H38/I38)-100% -> 0.053091311 | K38: =K39+K34 -> 1144012.6 | L38: =L39+L34 -> 987644.18 | M38: =(K38/L38)-100% -> 0.15832464 | N38: 1253933 | O38: 1269586 | P38: =(N38/O38)-100% -> -0.012329216
B39: =MONTH(A11) -> 10 | C39: International | D39: TEUs | E39: 113762 | F39: 118695 | G39: -0.0416 | H39: 128720 | I39: 112960 | J39: 0.1395 | K39: 136937 | L39: 119424 | M39: 0.1466 | N39: 138106 | O39: 139377 | P39: =(N39/O39)-100% -> -0.0091191517
B40: =MONTH(A11) -> 10 | C40: Kumulatif Domestic | D40: TEUs | E40: =E41+E36 -> 62749 | F40: =F41+F36 -> 73144 | G40: =(E40/F40)-100% -> -0.14211692 | H40: =H41+H36 -> 55251 | I40: =I41+I36 -> 69116 | J40: =(H40/I40)-100% -> -0.20060478 | K40: =K41+K36 -> 61043.697 | L40: =L41+L36 -> 53682.639 | M40: =(K40/L40)-100% -> 0.13712176 | N40: 53140 | O40: 72945 | P40: =(N40/O40)-100% -> -0.27150593
...

Sheet CONT THROUGHPUT
A1: DATE | B1: YEAR | C1: MONTH | D1: TEUS | E1: CATEGORY
A2: 44562 | B2: =YEAR(A2) -> 2022 | C2: =MONTH(A2) -> 1 | D2: 95784 | E2: INTERNATIONAL
A3: 44593 | B3: =YEAR(A3) -> 2022 | C3: =MONTH(A3) -> 2 | D3: 116266.75 | E3: INTERNATIONAL
A4: 44621 | B4: =YEAR(A4) -> 2022 | C4: =MONTH(A4) -> 3 | D4: 99208.75 | E4: INTERNATIONAL
A5: 44652 | B5: =YEAR(A5) -> 2022 | C5: =MONTH(A5) -> 4 | D5: 105519 | E5: INTERNATIONAL
A6: 44682 | B6: =YEAR(A6) -> 2022 | C6: =MONTH(A6) -> 5 | D6: 99338.25 | E6: INTERNATIONAL
A7: 44713 | B7: =YEAR(A7) -> 2022 | C7: =MONTH(A7) -> 6 | D7: 109829 | E7: INTERNATIONAL
A8: 44743 | B8: =YEAR(A8) -> 2022 | C8: =MONTH(A8) -> 7 | D8: 106382.5 | E8: INTERNATIONAL
A9: 44774 | B9: =YEAR(A9) -> 2022 | C9: =MONTH(A9) -> 8 | D9: 125414.25 | E9: INTERNATIONAL
A10: 44805 | B10: =YEAR(A10) -> 2022 | C10: =MONTH(A10) -> 9 | D10: 97950.5 | E10: INTERNATIONAL
A11: 44835 | B11: =YEAR(A11) -> 2022 | C11: =MONTH(A11) -> 10 | D11: 113761.75 | E11: INTERNATIONAL
A12: 44866 | B12: =YEAR(A12) -> 2022 | C12: =MONTH(A12) -> 11 | D12: 108161.25 | E12: INTERNATIONAL
A13: 44896 | B13: =YEAR(A13) -> 2022 | C13: =MONTH(A13) -> 12 | D13: 115879 | E13: INTERNATIONAL
... A27: 45323 | B27: =YEAR(A27) -> 2024 | C27: =MONTH(A27) -> 2 | D27: 115250 | E27: INTERNATIONAL
A28: 03/2024 | B28: =YEAR(A28) -> 2024 | C28: =MONTH(A28) -> 3 | D28: 125120 | E28: INTERNATIONAL
A29: 04/2024 | B29: =YEAR(A29) -> 2024 | C29: =MONTH(A29) -> 4 | D29: 101590 | E29: INTERNATIONAL

Sheet C.THR. DOM
A1: DATE | B1: YEAR | C1: MONTH | D1: TEUS
A2: 44562 | B2: 2022 | C2: 1 | D2: 6924 | E2: DOMESTIC
A3: 44593 | B3: 2022 | C3: 2 | D3: 7268 | E3: DOMESTIC
A4: 44621 | B4: 2022 | C4: 3 | D4: 6821 | E4: DOMESTIC
A5: 44652 | B5: 2022 | C5: 4 | D5: 7126 | E5: DOMESTIC
A6: 44682 | B6: 2022 | C6: 5 | D6: 6999 | E6: DOMESTIC
A7: 44713 | B7: 2022 | C7: 6 | D7: 7160 | E7: DOMESTIC
A8: 44743 | B8: 2022 | C8: 7 | D8: 5500 | E8: DOMESTIC
A9: 44774 | B9: 2022 | C9: 8 | D9: 6729 | E9: DOMESTIC
A10: 44805 | B10: 2022 | C10: 9 | D10: 4447 | E10: DOMESTIC
A11: 44835 | B11: 2022 | C11: 10 | D11: 3775 | E11: DOMESTIC
A12: 44866 | B12: 2022 | C12: 11 | D12: 4991 | E12: DOMESTIC
A13: 44896 | B13: 2022 | C13: 12 | D13: 4954 | E13: DOMESTIC
... A27: 45323 | B27: 2024 | C27: 2 | D27: 8028 | E27: DOMESTIC
A28: 03/2024 | B28: 2024 | C28: 2 | D28: 8647 | E28: DOMESTIC
A29: 04/2024 | B29: 2024 | C29: 2 | D29: 3697 | E29: DOMESTIC

Sheet V.OPR INT
A1: DATE | B1: YEAR | C1: MONTH | D1: LOP | E1: TEUS | F1: BOX | G1: DPP | H1: BCH | I1: BSH | J1: AVERAGE CD | K1: TEUS 2023 | L1: BOX 2023 | M1: DPP 2023 | N1: BCH 2023 | O1: BSH 2023 | P1: AVERAGE CD 2023
A2: 44927 | B2: =YEAR(A2) -> 2023 | C2: =MONTH(A2) -> 1 | D2: EMC | E2: 14609 | F2: 9643 | G2: 16341982320 | H2: 28.8 | I2: 48.32 | J2: 0 | K2: 14609 | L2: 9643 | M2: Rp. 16.341.982.320 | N2: 29 | O2: 48 | P2: 0
A3: 44928 | B3: =YEAR(A3) -> 2023 | C3: =MONTH(A3) -> 1 | D3: SSL | E3: 14466 | F3: 9926 | G3: 16655410181 | H3: 36.4 | I3: 83.92 | J3: 8 | K3: 14592 | L3: 9622 | M3: 16571826414 | N3: 29 | O3: 59 | P3: 8
A4: 44929 | B4: =YEAR(A4) -> 2023 | C4: =MONTH(A4) -> 1 | D4: CNC | E4: 11401 | F4: 7403 | G4: 12972661683 | H4: 31.5 | I4: 54.21 | J4: 2 | K4: 14466 | L4: 9926 | M4: Rp. 16.655.410.181 | N4: 36 | O4: 84 | P4: 2
A5: 44930 | B5: =YEAR(A5) -> 2023 | C5: =MONTH(A5) -> 1 | D5: MSC | E5: 11061 | F5: 7657 | G5: 13168083042 | H5: 29 | I5: 52.13 | J5: 4 | K5: 11061 | L5: 7657 | M5: Rp. 13.168.083.042 | N5: 29 | O5: 52 | P5: 4
A6: 44931 | B6: =YEAR(A6) -> 2023 | C6: =MONTH(A6) -> 1 | D6: MSK | E6: 9145 | F6: 5700 | G6: 10435664983 | H6: 28.8 | I6: 74.83 | J6: 3 | K6: 9145 | L6: 5700 | M6: Rp. 10.435.664.983 | N6: 29 | O6: 75 | P6: 3
A7: 44932 | B7: =YEAR(A7) -> 2023 | C7: =MONTH(A7) -> 1 | D7: COS | E7: 8393 | F7: 5678 | G7: 9725904427 | H7: 32.7 | I7: 68.11 | J7: 4 | K7: 8393 | L7: 5678 | M7: Rp. 9.725.904.427 | N7: 33 | O7: 68 | P7: 4
A8: 44933 | B8: =YEAR(A8) -> 2023 | C8: =MONTH(A8) -> 1 | D8: WHL | E8: 7155 | F8: 4721 | G8: 8407390538 | H8: 26.5 | I8: 42.46 | J8: 4 | K8: 7155 | L8: 4721 | M8: Rp. 8.407.390.538 | N8: 26 | O8: 42 | P8: 4
A9: 44934 | B9: =YEAR(A9) -> 2023 | C9: =MONTH(A9) -> 1 | D9: PIL | E9: 5757 | F9: 3893 | G9: 6714230932 | H9: 31 | I9: 57.22 | J9: 2 | K9: 5757 | L9: 3893 | M9: Rp. 6.714.230.932 | N9: 31 | O9: 57 | P9: 2
A10: 44935 | B10: =YEAR(A10) -> 2023 | C10: =MONTH(A10) -> 1 | D10: RCL | E10: 3889 | F10: 2691 | G10: 4541270822 | H10: 23.9 | I10: 42.06 | J10: 2 | K10: 3889 | L10: 2691 | M10: Rp. 4.541.270.822 | N10: 24 | O10: 42 | P10: 2
A11: 44936 | B11: =YEAR(A11) -> 2023 | C11: =MONTH(A11) -> 1 | D11: SIT | E11: 3208 | F11: 2210 | G11: 3936766752 | H11: 24 | I11: 30.29 | J11: 3 | K11: 3208 | L11: 2210 | M11: Rp. 3.936.766.752 | N11: 24 | O11: 30 | P11: 3
A12: 44937 | B12: =YEAR(A12) -> 2023 | C12: =MONTH(A12) -> 1 | D12: CMA | E12: 3191 | F12: 2219 | G12: 3599164731 | H12: 26.9 | I12: 63.15 | J12: 2 | K12: 2132 | L12: 1400 | M12: Rp. 2.349.174.700 | N12: 27 | O12: 45 | P12: 2
A13: 44938 | B13: =YEAR(A13) -> 2023 | C13: =MONTH(A13) -> 1 | D13: YML | E13: 2132 | F13: 1400 | G13: 2349174700 | H13: 27.3 | I13: 45.25 | J13: 2 | K13: 1305 | L13: 909 | M13: Rp. 1.552.933.479 | N13: 33 | O13: 50 | P13: 2
A14: 44939 | B14: =YEAR(A14) -> 2023 | C14: =MONTH(A14) -> 1 | D14: KMT | E14: 1305 | F14: 909 | G14: 1552933479 | H14: 33 | I14: 49.57 | J14: 0 | K14: 1210 | L14: 802 | M14: Rp. 1.326.466.739 | N14: 34 | O14: 61 | P14: 0
A15: 44940 | B15: =YEAR(A15) -> 2023 | C15: =MONTH(A15) -> 1 | D15: GSL | E15: 1210 | F15: 802 | G15: 1326466739 | H15: 34.2 | I15: 60.8 | J15: 3 | K15: 975 | L15: 690 | M15: Rp. 1.125.059.378 | N15: 35 | O15: 73 | P15: 3
A16: 44941 | B16: =YEAR(A16) -> 2023 | C16: =MONTH(A16) -> 1 | D16: OOL | E16: 975 | F16: 690 | G16: 1125059378 | H16: 34.6 | I16: 72.74 | J16: 2 | K16: 911 | L16: 643 | M16: Rp. 1.087.991.525 | N16: 25 | O16: 49 | P16: 2
A17: 44941 | B17: =YEAR(A17) -> 2023 | C17: 1 | D17: ONE | E17: 911 | F17: 643 | G17: 1087991525 | H17: 25.1 | I17: 48.71
A18: 44958 | B18: =YEAR(A18) -> 2023 | C18: =MONTH(A18) -> 2 | D18: MSK | E18: 13960 | F18: 8933 | G18: 15836582394 | H18: 32 | I18: 67.57 | J18: 3 | K18: 27386 | L18: 18296 | M18: 31112551732 | N18: 35 | O18: 83 | P18: 3
A19: 44959 | B19: =YEAR(A19) -> 2023 | C19: =MONTH(A19) -> 2 | D19: SSL | E19: 12920 | F19: 8370 | G19: 14457141551 | H19: 33.7 | I19: 81.39 | J19: 7 | K19: 27012 | L19: 17854 | M19: 30458217308 | N19: 31 | O19: 60 | P19: 7
A20: 44960 | B20: =YEAR(A20) -> 2023 | C20: =MONTH(A20) -> 2 | D20: EMC | E20: 12126 | F20: 8386 | G20: 13294331286 | H20: 32.8 | I20: 56.29 | J20: 10 | K20: 26735 | L20: 18029 | M20: 29636313605 | N20: 31 | O20: 52 | P20: 10
A21: 44961 | B21: =YEAR(A21) -> 2023 | C21: =MONTH(A21) -> 2 | D21: COS | E21: 10441 | F21: 6975 | G21: 11775696904 | H21: 31 | I21: 64.34 | J21: 2 | K21: 23105 | L21: 14633 | M21: 26272247377 | N21: 30 | O21: 71 | P21: 2
A22: 44962 | B22: =YEAR(A22) -> 2023 | C22: =MONTH(A22) -> 2 | D22: CNC | E22: 10031 | F22: 6554 | G22: 11236123104 | H22: 28.8 | I22: 45.8 | J22: 4 | K22: 19461 | L22: 13607 | M22: 23177294547 | N22: 29 | O22: 49 | P22: 4
A23: 44963 | B23: =YEAR(A23) -> 2023 | C23: =MONTH(A23) -> 2 | D23: MSC | E23: 8400 | F23: 5950 | G23: 10009211505 | H23: 29.1 | I23: 45.78 | J23: 4 | K23: 18834 | L23: 12653 | M23: 21501601331 | N23: 32 | O23: 66 | P23: 4
A24: 44964 | B24: =YEAR(A24) -> 2023 | C24: =MONTH(A24) -> 2 | D24: WHL | E24: 7406 | F24: 4639 | G24: 8221317255 | H24: 24.4 | I24: 39.45 | J24: 3 | K24: 14561 | L24: 9360 | M24: 16628707793 | N24: 25 | O24: 41 | P24: 3
A25: 44965 | B25: =YEAR(A25) -> 2023 | C25: =MONTH(A25) -> 2 | D25: RCL | E25: 6379 | F25: 4462 | G25: 7159027892 | H25: 23 | I25: 44.07 | J25: 2 | K25: 10268 | L25: 7153 | M25: 11700298714 | N25: 23 | O25: 43 | P25: 2
A26: 44966 | B26: =YEAR(A26) -> 2023 | C26: =MONTH(A26) -> 2 | D26: OOL | E26: 2465 | F26: 1627 | G26: 2745250265 | H26: 27.3 | I26: 51.77 | J26: 2 | K26: 7476 | L26: 5187 | M26: 8721350865 | N26: 31 | O26: 48 | P26: 2
A27: 44967 | B27: =YEAR(A27) -> 2023 | C27: =MONTH(A27) -> 2 | D27: KMT | E27: 2410 | F27: 1778 | G27: 2897676897 | H27: 23.6 | I27: 38.54 | J27: 3 | K27: 5540 | L27: 3866 | M27: 6761959104 | N27: 24 | O27: 27 | P27: 3
A28: 44968 | B28: =YEAR(A28) -> 2023 | C28: =MONTH(A28) -> 2 | D28: CMA | E28: 2389 | F28: 1678 | G28: 2650267790 | H28: 36.1 | I28: 77.54 | J28: 2 | K28: 3715 | L28: 2687 | M28: 4450610376 | N28: 28 | O28: 44 | P28: 2
A29: 44969 | B29: =YEAR(A29) -> 2023 | C29: =MONTH(A29) -> 2 | D29: SIT | E29: 2332 | F29: 1656 | G29: 2825192352 | H29: 23.1 | I29: 24.6 | J29: 2 | K29: 3440 | L29: 2317 | M29: 3870309643 | N29: 31 | O29: 62 | P29: 2
... A93: 45087 | B93: =YEAR(A93) -> 2023 | C93: =MONTH(A93) -> 6 | D93: OOL | E93: 2513 | F93: 1734 | G93: 2782051095 | H93: 21.2 | I93: 48.24 | J93: 2 | K93: 14022 | L93: 9832 | M93: 16506778477 | N93: 25 | O93: 42 | P93: 2
A94: 45088 | B94: =YEAR(A94) -> 2023 | C94: =MONTH(A94) -> 6 | D94: ONE | E94: 2477 | F94: 1705 | G94: 2875268489 | H94: 36.5 | I94: 67.76 | J94: 2 | K94: 10615 | L94: 7168 | M94: Rp 11,452,777,869 | N94: 25 | O94: 51 | P94: 2
A95: 45089 | B95: =YEAR(A95) -> 2023 | C95: =MONTH(A95) -> 6 | D95: CMA | E95: 2306 | F95: 1513 | G95: 2475320743 | H95: 21.9 | I95: 51.23 | J95: 2 | K95: 10236 | L95: 7249 | M95: Rp 11,248,304,961 | N95: 34 | O95: 59 | P95: 2
A96: 45090 | B96: =YEAR(A96) -> 2023 | C96: =MONTH(A96) -> 6 | D96: GSL | E96: 1409 | F96: 973 | G96: 1521471111 | H96: 28.3 | I96: 60.64 | J96: 0 | K96: 8382 | L96: 5847 | M96: Rp 9,771,781,402 | N96: 30 | O96: 44 | P96: 0
A97: 45091 | B97: =YEAR(A97) -> 2023 | C97: =MONTH(A97) -> 6 | D97: YML | E97: 1176 | F97: 767 | G97: 1254782978 | H97: 24.5 | I97: 53.27 | J97: 2 | K97: 10723 | L97: 7352 | M97: Rp 11,819,763,544 | N97: 26 | O97: 56 | P97: 2
A98: 45092 | B98: =YEAR(A98) -> 2023 | C98: =MONTH(A98) -> 6 | D98: LMA | E98: 682 | F98: 505 | G98: 6.6913971e+08 | H98: 20.9 | I98: 21.55 | J98: 2 | K98: 8511 | L98: 5845 | M98: Rp 9,901,929,726 | N98: 29 | O98: 52 | P98: 2
A99: 45093 | B99: =YEAR(A99) -> 2023 | C99: =MONTH(A99) -> 6 | D99: ANL | E99: 492 | F99: 309 | G99: 536995672 | H99: 20.2 | I99: 22.91 | J99: 2 | K99: 2603 | L99: 1646 | M99: Rp3,093,903,137 | N99: 21 | O99: 17 | P99: 2
A100: 45094 | B100: =YEAR(A100) -> 2023 | C100: =MONTH(A100) -> 6 | D100: BEN | E100: 166 | F100: 117 | G100: 1.6117263e+08 | H100: 36.8 | I100: 21.33 | J100: 0 | K100: 1073 | L100: 808 | M100: Rp 1,042,143,789 | N100: 20 | O100: 20 | P100: 0
A101: 45108 | B101: =YEAR(A101) -> 2023 | C101: =MONTH(A101) -> 7 | D101: CNC | E101: 32032 | F101: 20344 | G101: 34950935638 | H101: 31.7 | I101: 73.19 | J101: 10 | K101: 152227 | L101: 98621 | M101: 167306875089 | N101: 29 | O101: 61 | P101: 10
A102: 45109 | B102: =YEAR(A102) -> 2023 | C102: =MONTH(A102) -> 7 | D102: MSK | E102: 19631 | F102: 12226 | G102: 21836793254 | H102: 30.5 | I102: 81.35 | J102: 9 | K102: 108472 | L102: 72004 | M102: 116641804089 | N102: 29 | O102: 54 | P102: 9
A103: 45110 | B103: =YEAR(A103) -> 2023 | C103: =MONTH(A103) -> 7 | D103: EMC | E103: 18295 | F103: 12289 | G103: 19280598136 | H103: 28.6 | I103: 61.13 | J103: 3 | K103: 105029 | L103: 65633 | M103: 116570096794 | N103: 31 | O103: 73 | P103: 3
...

Sheet V.OPR DOM
A1: DATE | B1: YEAR | C1: MONTH | D1: LOP | E1: TEUS | F1: BOX | G1: DPP | H1: BCH | I1: BSH | J1: AVERAGE CD | K1: TEUS 2023 | L1: BOX 2023 | M1: DPP 2023 | N1: BCH 2023 | O1: BSH 2023 | P1: AVERAGE CD 2023
A2: 44927 | B2: =YEAR(A2) -> 2023 | C2: =MONTH(A2) -> 1 | D2: SPI | E2: 548 | F2: 477 | G2: 227765975 | H2: 23.77 | I2: 19.44 | J2: 0.8 | K2: 4170 | L2: 3762 | M2: Rp. 2.113.335.293 | N2: 26 | O2: 17 | P2: 0.8
A3: 44928 | B3: =YEAR(A3) -> 2023 | C3: =MONTH(A3) -> 1 | D3: TIL | E3: 4170 | F3: 3762 | G3: 2113335293 | H3: 25.56 | I3: 17.3 | J3: 0.8 | K3: 548 | L3: 477 | M3: Rp. 227.765.975 | N3: 24 | O3: 19 | P3: 0.8
A4: 44958 | B4: =YEAR(A4) -> 2023 | C4: =MONTH(A4) -> 2 | D4: TIL | E4: 4091 | F4: 3729 | G4: 1931500188 | H4: 25 | I4: 16 | J4: 0.9 | K4: 8261 | L4: 7491 | M4: 4044835481 | N4: 25 | O4: 17 | P4: 0.9
A5: 44959 | B5: =YEAR(A5) -> 2023 | C5: =MONTH(A5) -> 2 | D5: SPI | E5: 180 | F5: 168 | G5: 96700294 | H5: 24 | I5: 12 | J5: 0.8 | K5: 728 | L5: 645 | M5: 324466269 | N5: 24 | O5: 16 | P5: 0.8
A6: 44986 | B6: =YEAR(A6) -> 2023 | C6: =MONTH(A6) -> 3 | D6: TIL | E6: 6209 | F6: 5468 | G6: 2773457701 | H6: 28 | I6: 18 | J6: 0.9 | K6: 14470 | L6: 12959 | M6: 6818293182 | N6: 26 | O6: 17 | P6: 0.9
A7: 44987 | B7: =YEAR(A7) -> 2023 | C7: =MONTH(A7) -> 3 | D7: SPI | E7: 923 | F7: 860 | G7: 622549497 | H7: 21 | I7: 14 | J7: 0.7 | K7: 1651 | L7: 1505 | M7: 947015766 | N7: 23 | O7: 15 | P7: 0.7
A8: 45017 | B8: =YEAR(A8) -> 2023 | C8: =MONTH(A8) -> 4 | D8: TIL | E8: 4123 | F8: 3647 | G8: 1887616843 | H8: 26 | I8: 19 | J8: 0.9 | K8: 18593 | L8: 16606 | M8: 8705910025 | N8: 26 | O8: 18 | P8: 0.9
A9: 45018 | B9: =YEAR(A9) -> 2023 | C9: =MONTH(A9) -> 4 | D9: SPI | E9: 0 | F9: 0 | G9: 0 | H9: 0 | I9: 0 | J9: 0 | K9: 1651 | L9: 1505 | M9: 947015766 | N9: 23 | O9: 15 | P9: 0
A10: 45019 | B10: =YEAR(A10) -> 2023 | C10: =MONTH(A10) -> 4 | D10: TAS | E10: 393 | F10: 329 | G10: 249286874 | H10: 21 | I10: 14 | J10: 1.2 | K10: 393 | L10: 329 | M10: 249286874 | N10: 21 | O10: 14 | P10: 1.2
A11: 45047 | B11: =YEAR(A11) -> 2023 | C11: =MONTH(A11) -> 5 | D11: TIL | E11: 2915 | F11: 2639 | G11: 1686764192 | H11: 25 | I11: 19 | J11: 1 | K11: 21508 | L11: 19245 | M11: 10392674217 | N11: 26 | O11: 18 | P11: 1
A12: 45048 | B12: =YEAR(A12) -> 2023 | C12: =MONTH(A12) -> 5 | D12: SPI | E12: 0 | F12: 0 | G12: 0 | H12: 0 | I12: 0 | J12: 0 | K12: 1651 | L12: 1505 | M12: 947015766 | N12: 23 | O12: 15 | P12: 0
A13: 45049 | B13: =YEAR(A13) -> 2023 | C13: =MONTH(A13) -> 5 | D13: TAS | E13: 727 | F13: 567 | G13: 371938289 | H13: 20 | I13: 21 | J13: 1.2 | K13: 1120 | L13: 896 | M13: 621225163 | N13: 21 | O13: 18 | P13: 1.2
A14: 45078 | B14: =YEAR(A14) -> 2023 | C14: =MONTH(A14) -> 6 | D14: TIL | E14: 2823 | F14: 2574 | G14: 1014365003 | H14: 29 | I14: 26 | J14: 1 | K14: 24331 | L14: 21819 | M14: 11407039220 | N14: 26 | O14: 19 | P14: 1
A15: 45079 | B15: =YEAR(A15) -> 2023 | C15: =MONTH(A15) -> 6 | D15: SPI | E15: 2405 | F15: 2173 | G15: 1315460992 | H15: 28 | I15: 24 | J15: 1.2 | K15: 4056 | L15: 3678 | M15: 2262476.8 | N15: 24 | O15: 18 | P15: 1.2
... A75: 45413 | B75: =YEAR(A75) -> 2024 | C75: =MONTH(A75) -> 5 | D75: PNJ | E75: 0 | F75: 0 | G75: 0 | H75: 0 | I75: 0 | J75: 0 | K75: 0 | L75: 0 | M75: 0 | N75: 0 | O75: 0 | P75: 0
A76: 45413 | B76: =YEAR(A76) -> 2024 | C76: =MONTH(A76) -> 5 | D76: TAS | E76: - | F76: - | G76: Rp- | H76: - | I76: - | J76: 0 | K76: 0 | L76: 0 | M76: 0 | N76: 0 | O76: 0 | P76: 0
A77: 45444 | B77: =YEAR(A77) -> 2024 | C77: =MONTH(A77) -> 6 | D77: TIL | E77: 3982 | F77: 3642 | G77: 1864907539 | H77: 29 | I77: 23 | J77: 0.96 | K77: 0 | L77: 0 | M77: 0 | N77: 0 | O77: 0 | P77: 0
A78: 45444 | B78: =YEAR(A78) -> 2024 | C78: =MONTH(A78) -> 6 | D78: SPI | E78: 2583 | F78: 2352 | G78: 1394637184 | H78: 21 | I78: 14 | J78: 0.92 | K78: 0 | L78: 0 | M78: 0 | N78: 0 | O78: 0 | P78: 0
A79: 45444 | B79: =YEAR(A79) -> 2024 | C79: =MONTH(A79) -> 6 | D79: MPN | E79: 1828 | F79: 1016 | G79: 1753069425 | H79: 48 | I79: 54 | J79: 0.77 | K79: 0 | L79: 0 | M79: 0 | N79: 0 | O79: 0 | P79: 0
A80: 45444 | B80: =YEAR(A80) -> 2024 | C80: =MONTH(A80) -> 6 | D80: ICON | E80: 0 | F80: 0 | G80: 0 | H80: 0 | I80: 0 | J80: 0 | K80: 0 | L80: 0 | M80: 0 | N80: 0 | O80: 0 | P80: 0
A81: 45444 | B81: =YEAR(A81) -> 2024 | C81: =MONTH(A81) -> 6 | D81: PNJ | E81: 54 | F81: 46 | G81: 29756500 | H81: 27 | I81: 10 | J81: 1.14 | K81: 0 | L81: 0 | M81: 0 | N81: 0 | O81: 0 | P81: 0
A82: 45444 | B82: =YEAR(A82) -> 2024 | C82: =MONTH(A82) -> 6 | D82: TAS | E82: 0 | F82: 0 | G82: 0 | H82: 0 | I82: 0 | J82: 0 | K82: 0 | L82: 0 | M82: 0 | N82: 0 | O82: 0 | P82: 0
A83: 45474 | B83: =YEAR(A83) -> 2024 | C83: =MONTH(A83) -> 7 | D83: SPI | E83: 2069 | F83: 1918 | G83: 1234651848 | H83: 26 | I83: 57 | J83: 0.91 | K83: 0 | L83: 0 | M83: 0 | N83: 0 | O83: 0 | P83: 0
A84: 45475 | B84: =YEAR(A84) -> 2024 | C84: =MONTH(A84) -> 7 | D84: MPN | E84: 242 | F84: 232 | G84: 84771495 | H84: 25 | I84: 47 | J84: 0.97 | K84: 0 | L84: 0 | M84: 0 | N84: 0 | O84: 0 | P84: 0
A85: 45476 | B85: =YEAR(A85) -> 2024 | C85: =MONTH(A85) -> 7 | D85: MAA | E85: 0 | F85: 0 | G85: 0 | H85: 0 | I85: 0 | J85: 0 | K85: 0 | L85: 0 | M85: 0 | N85: 0 | O85: 0 | P85: 0
A86: 45477 | B86: =YEAR(A86) -> 2024 | C86: =MONTH(A86) -> 7 | D86: ICN | E86: 503 | F86: 398 | G86: 186379965 | H86: 27 | I86: 70 | J86: 1.1 | K86: 0 | L86: 0 | M86: 0 | N86: 0 | O86: 0 | P86: 0
A87: 45478 | B87: =YEAR(A87) -> 2024 | C87: =MONTH(A87) -> 7 | D87: TAS | E87: 0 | F87: 0 | G87: 0 | H87: 0 | I87: 0 | J87: 0 | K87: 0 | L87: 0 | M87: 0 | N87: 0 | O87: 0 | P87: 0
A88: 45479 | B88: =YEAR(A88) -> 2024 | C88: =MONTH(A88) -> 7 | D88: CTP | E88: 0 | F88: 0 | G88: 0 | H88: 0 | I88: 0 | J88: 0 | K88: 0 | L88: 0 | M88: 0 | N88: 0 | O88: 0 | P88: 0
... A103: 45536 | B103: =YEAR(A103) -> 2024 | C103: =MONTH(A103) -> 9 | D103: TIL | E103: 4980 | F103: 4458 | G103: 2289820635 | H103: 26.36 | I103: 20.22 | J103: 0.9 | K103: 0 | L103: 0 | M103: 0 | N103: 0 | O103: 0 | P103: 0
A104: 45566 | B104: 2024 | C104: 10 | D104: SPI | E104: 711 | F104: 624 | G104: 324916395 | H104: 16 | I104: 12 | J104: 1 | K104: 0 | L104: 0 | M104: 0 | N104: 0 | O104: 0 | P104: 0
A105: 45566 | B105: 2024 | C105: 10 | D105: TIL | E105: 4980 | F105: 4458 | G105: 2289820635 | H105: 26 | I105: 20 | J105: 0.9 | K105: 0 | L105: 0 | M105: 0 | N105: 0 | O105: 0 | P105: 0
A106: 45566 | B106: 2024 | C106: 10 | D106: MPN | E106: 19 | F106: 12 | G106: 8480494 | H106: 28 | I106: 1 | J106: 0.9 | K106: 0 | L106: 0 | M106: 0 | N106: 0 | O106: 0 | P106: 0
A107: 45566 | B107: 2024 | C107: 10 | D107: ICN | E107: 134 | F107: 100 | G107: 41787020 | H107: 17 | I107: 20 | J107: 1 | K107: 0 | L107: 0 | M107: 0 | N107: 0 | O107: 0 | P107: 0
A108: 45567 | B108: 2024 | C108: 10 | D108: PNJ | E108: 61 | F108: 56 | G108: 32059377 | H108: 39 | I108: 15 | J108: 1 | K108: 0 | L108: 0 | M108: 0 | N108: 0 | O108: 0 | P108: 0
A109: 45597 | B109: 2024 | C109: 11 | D109: SPI | E109: 1067 | F109: 836 | G109: 385967359 | H109: 18 | I109: 15 | J109: 0.6 | K109: 0 | L109: 0 | M109: 0 | N109: 0 | O109: 0 | P109: 0
A110: 45597 | B110: 2024 | C110: 11 | D110: MPN | E110: 641 | F110: 516 | G110: 259250047 | H110: 21 | I110: 14 | J110: 1 | K110: 0 | L110: 0 | M110: 0 | N110: 0 | O110: 0 | P110: 0
A111: 45597 | B111: 2024 | C111: 11 | D111: MAA | E111: 0 | F111: 0 | G111: 0 | H111: 0 | I111: 0 | J111: 0 | K111: 0 | L111: 0 | M111: 0 | N111: 0 | O111: 0 | P111: 0
A112: 45597 | B112: 2024 | C112: 11 | D112: ICN | E112: 152 | F112: 132 | G112: 48093290 | H112: 23 | I112: 7 | J112: 1 | K112: 0 | L112: 0 | M112: 0 | N112: 0 | O112: 0 | P112: 0
A113: 45597 | B113: 2024 | C113: 11 | D113: TIL | E113: 4401 | F113: 3941 | G113: 1979038105 | H113: 27 | I113: 20 | J113: 0.9 | K113: 0 | L113: 0 | M113: 0 | N113: 0 | O113: 0 | P113: 0
...

Sheet B.OPR INT
A1: DATE | B1: YEAR | C1: MONTH | D1: LOP | E1: 2022 (TEUS) | F1: 2023 (TEUS) | G1: 2024 (TEUS) | H1: 2025 (TEUS) | I1: 2026 (TEUS) | J1: %
A2: 45292 | B2: =YEAR(A2) -> 2024 | C2: =MONTH(A2) -> 1 | D2: CMA | E2: 12085 | F2: 14158 | G2: 10480 | J2: 0.1715
A3: 45293 | B3: =YEAR(A3) -> 2024 | C3: =MONTH(A3) -> 1 | D3: EMC | E3: 12494 | F3: 13601 | G3: 10651 | J3: 0.0886
A4: 45294 | B4: =YEAR(A4) -> 2024 | C4: =MONTH(A4) -> 1 | D4: MSC | E4: 11120 | F4: 10754 | G4: 10412 | J4: -0.0329
A5: 45295 | B5: =YEAR(A5) -> 2024 | C5: =MONTH(A5) -> 1 | D5: ONE | E5: 12015 | F5: 10592 | G5: 12560 | J5: -0.1184
A6: 45296 | B6: =YEAR(A6) -> 2024 | C6: =MONTH(A6) -> 1 | D6: MSK | E6: 14065 | F6: 9899 | G6: 14137 | J6: -0.2962
A7: 45297 | B7: =YEAR(A7) -> 2024 | C7: =MONTH(A7) -> 1 | D7: WHL | E7: 6221 | F7: 7028 | G7: 6119 | J7: 0.1297
A8: 45298 | B8: =YEAR(A8) -> 2024 | C8: =MONTH(A8) -> 1 | D8: COSCO | E8: 10768 | F8: 6956 | G8: 8280 | J8: -0.354
A9: 45299 | B9: =YEAR(A9) -> 2024 | C9: =MONTH(A9) -> 1 | D9: OOCL | E9: 5100 | F9: 5333 | G9: 5378 | J9: 0.0457
A10: 45300 | B10: =YEAR(A10) -> 2024 | C10: =MONTH(A10) -> 1 | D10: RCL | E10: 2297 | F10: 3394 | G10: 3875 | J10: 4.4919
A11: 45301 | B11: =YEAR(A11) -> 2024 | C11: =MONTH(A11) -> 1 | D11: SITC | E11: 2275 | F11: 3267 | G11: 4316 | J11: -0.2173
A12: 45302 | B12: =YEAR(A12) -> 2024 | C12: =MONTH(A12) -> 1 | D12: HPL | E12: 3316 | F12: 0 | G12: 0 | J12: 0.3761
A13: 45303 | B13: =YEAR(A13) -> 2024 | C13: =MONTH(A13) -> 1 | D13: YML | E13: 1186 | F13: 2614 | G13: 2133 | J13: 0.149
... A18: 45308 | B18: =YEAR(A18) -> 2024 | C18: =MONTH(A18) -> 1 | D18: HMM | E18: 1559 | F18: 428 | G18: 658 | J18: -0.7255
A19: 45309 | B19: =YEAR(A19) -> 2024 | C19: =MONTH(A19) -> 1 | D19: ANL | E19: - | F19: 377 | G19: 0 | J19: 0
A20: 45310 | B20: =YEAR(A20) -> 2024 | C20: =MONTH(A20) -> 1 | D20: XCL | E20: 1542 | F20: 199 | G20: 282 | J20: -0.8709
A21: 45311 | B21: =YEAR(A21) -> 2024 | C21: =MONTH(A21) -> 1 | D21: KRL | E21: - | F21: 0 | G21: 0 | J21: 0
A22: 45312 | B22: =YEAR(A22) -> 2024 | C22: =MONTH(A22) -> 1 | D22: KSL | E22: - | F22: 0 | G22: 0 | J22: 0
A23: 45313 | B23: =YEAR(A23) -> 2024 | C23: =MONTH(A23) -> 1 | D23: MELL | E23: 255 | F23: 0 | G23: 0 | J23: -1
A24: 45314 | B24: =YEAR(A24) -> 2024 | C24: =MONTH(A24) -> 1 | D24: OTHER | E24: 2347 | F24: 2819 | G24: 2500 | J24: 0.3805
A25: 45323 | B25: =YEAR(A25) -> 2024 | C25: =MONTH(A25) -> 2 | D25: EMC | E25: 26036 | F25: 12759 | G25: 10830 | J25: 0.0124
A26: 45324 | B26: =YEAR(A26) -> 2024 | C26: =MONTH(A26) -> 2 | D26: CMA | E26: 25419 | F26: 12019 | G26: 8360 | J26: 0.0298
A27: 45325 | B27: =YEAR(A27) -> 2024 | C27: =MONTH(A27) -> 2 | D27: MSK | E27: 27297 | F27: 13383 | G27: 14749 | J27: -0.1471
A28: 45326 | B28: =YEAR(A28) -> 2024 | C28: =MONTH(A28) -> 2 | D28: ONE | E28: 21359 | F28: 9316 | G28: 11242 | J28: -0.0679
A29: 45327 | B29: =YEAR(A29) -> 2024 | C29: =MONTH(A29) -> 2 | D29: MSC | E29: 21751 | F29: 8157 | G29: 9565 | J29: -0.1306
A30: 45328 | B30: =YEAR(A30) -> 2024 | C30: =MONTH(A30) -> 2 | D30: COSCO | E30: 23839 | F30: 7269 | G30: 9678 | J30: -0.4033
A31: 45329 | B31: =YEAR(A31) -> 2024 | C31: =MONTH(A31) -> 2 | D31: WHL | E31: 13712 | F31: 7005 | G31: 6126 | J31: 0.0234
A32: 45330 | B32: =YEAR(A32) -> 2024 | C32: =MONTH(A32) -> 2 | D32: OOCL | E32: 9161 | F32: 5728 | G32: 6453 | J32: 0.2074
A33: 45331 | B33: =YEAR(A33) -> 2024 | C33: =MONTH(A33) -> 2 | D33: RCL | E33: 1061 | F33: 3414 | G33: 3777 | J33: 5.4166
A34: 45332 | B34: =YEAR(A34) -> 2024 | C34: =MONTH(A34) -> 2 | D34: OTHER | E34: 4257 | F34: 2038 | G34: 2015 | J34: 0.4733
... A41: 45339 | B41: =YEAR(A41) -> 2024 | C41: =MONTH(A41) -> 2 | D41: SSL | E41: 3774 | F41: 863 | G41: 1025 | J41: -0.5488
A42: 45340 | B42: =YEAR(A42) -> 2024 | C42: =MONTH(A42) -> 2 | D42: ANL | E42: - | F42: 575 | G42: 0 | J42: 0
A43: 45341 | B43: =YEAR(A43) -> 2024 | C43: =MONTH(A43) -> 2 | D43: HMM | E43: 3142 | F43: 453 | G43: 632 | J43: -0.7196
A44: 45342 | B44: =YEAR(A44) -> 2024 | C44: =MONTH(A44) -> 2 | D44: XCL | E44: 2448 | F44: 251 | G44: 216 | J44: -0.8162
A45: 45343 | B45: =YEAR(A45) -> 2024 | C45: =MONTH(A45) -> 2 | D45: MELL | E45: 261 | F45: 80 | G45: 0 | J45: -0.6935
A46: 45344 | B46: =YEAR(A46) -> 2024 | C46: =MONTH(A46) -> 2 | D46: KRL | E46: 206 | F46: 70 | G46: 0 | J46: -0.6602
A47: 45345 | B47: =YEAR(A47) -> 2024 | C47: =MONTH(A47) -> 2 | D47: KSL | E47: - | F47: 0 | G47: 0 | J47: 0
A48: 45352 | B48: =YEAR(A48) -> 2024 | C48: =MONTH(A48) -> 3 | D48: EMC | E48: 38881 | F48: 17518 | G48: 16744 | J48: 0.1285
A49: 45353 | B49: =YEAR(A49) -> 2024 | C49: =MONTH(A49) -> 3 | D49: CMA | E49: 34249 | F49: 16376 | G49: 17213 | J49: 0.2425
A50: 45354 | B50: =YEAR(A50) -> 2024 | C50: =MONTH(A50) -> 3 | D50: MSK | E50: 41446 | F50: 13068 | G50: 14308 | J50: -0.123
...

Sheet B.OPR DOM
A1: DATE | B1: YEAR | C1: MONTH | D1: LOP | E1: 2022 (TEUS) | F1: 2023 (TEUS) | G1: 2024 (TEUS) | H1: 2025 (TEUS) | I1: 2026 (TEUS) | J1: %
A2: 45292 | B2: =YEAR(A2) -> 2024 | C2: =MONTH(A2) -> 1 | D2: TANTO | E2: 3232 | F2: 3547 | G2: 4338 | J2: 0.0817
A3: 45292 | B3: =YEAR(A3) -> 2024 | C3: =MONTH(A3) -> 1 | D3: SPIL | E3: 2438 | F3: 477 | G3: 5558 | J3: -0.7752
A4: 45292 | B4: =YEAR(A4) -> 2024 | C4: =MONTH(A4) -> 1 | D4: MERATUS | E4: - | F4: 172 | G4: 191 | J4: 0
A5: 45292 | B5: =YEAR(A5) -> 2024 | C5: =MONTH(A5) -> 1 | D5: TEMAS | E5: - | F5: 0 | G5: 0 | J5: 0
A6: 45292 | B6: =YEAR(A6) -> 2024 | C6: =MONTH(A6) -> 1 | D6: ICON | E6: 2543 | F6: 0 | G6: 0 | J6: -1
A7: 45323 | B7: =YEAR(A7) -> 2024 | C7: =MONTH(A7) -> 2 | D7: TANTO | E7: 4185 | F7: 4081 | G7: 4051 | J7: 0.573
A8: 45323 | B8: =YEAR(A8) -> 2024 | C8: =MONTH(A8) -> 2 | D8: SPIL | E8: 4171 | F8: 180 | G8: 3601 | J8: -0.8255
A9: 45323 | B9: =YEAR(A9) -> 2024 | C9: =MONTH(A9) -> 2 | D9: MERATUS | E9: - | F9: 225 | G9: 0 | J9: 0
A10: 45323 | B10: =YEAR(A10) -> 2024 | C10: =MONTH(A10) -> 2 | D10: TEMAS | E10: 6077 | F10: 0 | G10: 0 | J10: -1
A11: 45323 | B11: =YEAR(A11) -> 2024 | C11: =MONTH(A11) -> 2 | D11: ICON | E11: - | F11: 0 | G11: 0 | J11: 0
A12: 45352 | B12: =YEAR(A12) -> 2024 | C12: =MONTH(A12) -> 3 | D12: TANTO | E12: 3549 | F12: 5452 | G12: 5594 | J12: 1.3435
A13: 45352 | B13: =YEAR(A13) -> 2024 | C13: =MONTH(A13) -> 3 | D13: SPIL | E13: 5684 | F13: 859 | G13: 2383 | J13: -0.7097
A14: 45352 | B14: =YEAR(A14) -> 2024 | C14: =MONTH(A14) -> 3 | D14: MERATUS | E14: - | F14: 140 | G14: 0 | J14: 0
A15: 45352 | B15: =YEAR(A15) -> 2024 | C15: =MONTH(A15) -> 3 | D15: ICON | E15: 9318 | F15: - | G15: 399 | J15: -1
A16: 45352 | B16: =YEAR(A16) -> 2024 | C16: =MONTH(A16) -> 3 | D16: TEMAS | E16: - | F16: - | G16: 0 | J16: 0
A17: 45383 | B17: =YEAR(A17) -> 2024 | C17: =MONTH(A17) -> 4 | D17: TANTO | E17: 8966 | F17: 4115 | G17: 2879 | J17: 0.0539
A18: 45383 | B18: =YEAR(A18) -> 2024 | C18: =MONTH(A18) -> 4 | D18: SPIL | E18: 7940 | F18: 0 | G18: 636 | J18: -0.7922
A19: 45383 | B19: =YEAR(A19) -> 2024 | C19: =MONTH(A19) -> 4 | D19: MERATUS | E19: 63 | F19: 33 | G19: 294 | J19: 10.3492
A20: 45383 | B20: =YEAR(A20) -> 2024 | C20: =MONTH(A20) -> 4 | D20: ICON | E20: 11611 | F20: 0 | G20: 198 | J20: -1
A21: 45383 | B21: =YEAR(A21) -> 2024 | C21: =MONTH(A21) -> 4 | D21: TEMAS | E21: - | F21: 220 | G21: 0 | J21: 0
A22: 45413 | B22: =YEAR(A22) -> 2024 | C22: =MONTH(A22) -> 5 | D22: TANTO | E22: 12171 | F22: 2915 | G22: 1622 | J22: 0.7423
A23: 45413 | B23: =YEAR(A23) -> 2024 | C23: =MONTH(A23) -> 5 | D23: SPIL | E23: 8871 | F23: 0 | G23: 1861 | J23: -0.814
A24: 45413 | B24: =YEAR(A24) -> 2024 | C24: =MONTH(A24) -> 5 | D24: MERATUS | E24: 63 | F24: 15 | G24: 299 | J24: 10.5873
A25: 45413 | B25: =YEAR(A25) -> 2024 | C25: =MONTH(A25) -> 5 | D25: ICON | E25: 13949 | F25: 0 | G25: 0 | J25: -1
A26: 45413 | B26: =YEAR(A26) -> 2024 | C26: =MONTH(A26) -> 5 | D26: TEMAS | E26: - | F26: 510 | G26: 0 | J26: 0
A27: 45444 | B27: =YEAR(A27) -> 2024 | C27: =MONTH(A27) -> 6 | D27: TANTO | E27: 15610 | F27: 2823 | G27: 3982 | J27: 0.5393
A28: 45444 | B28: =YEAR(A28) -> 2024 | C28: =MONTH(A28) -> 6 | D28: SPIL | E28: 10417 | F28: 2128 | G28: 2582 | J28: -0.6373
A29: 45444 | B29: =YEAR(A29) -> 2024 | C29: =MONTH(A29) -> 6 | D29: MERATUS | E29: 63 | F29: 128 | G29: 136 | J29: 12.619
A30: 45444 | B30: =YEAR(A30) -> 2024 | C30: =MONTH(A30) -> 6 | D30: ICON | E30: 16437 | F30: 0 | G30: 0 | J30: -1
A31: 45444 | B31: =YEAR(A31) -> 2024 | C31: =MONTH(A31) -> 6 | D31: TEMAS | E31: - | F31: 127 | G31: 0 | J31: 0
A32: 45474 | B32: =YEAR(A32) -> 2024 | C32: =MONTH(A32) -> 7 | D32: TANTO | E32: 17213 | F32: 677 | G32: 3226 | J32: 0.4353
A33: 45474 | B33: =YEAR(A33) -> 2024 | C33: =MONTH(A33) -> 7 | D33: SPIL | E33: 11331 | F33: 1097 | G33: 1403 | J33: -0.5698
A34: 45474 | B34: =YEAR(A34) -> 2024 | C34: =MONTH(A34) -> 7 | D34: MERATUS | E34: 67 | F34: 628 | G34: 494 | J34: 21.1791
A35: 45474 | B35: =YEAR(A35) -> 2024 | C35: =MONTH(A35) -> 7 | D35: TEMAS | E35: - | F35: 53 | G35: 241 | J35: 0
A36: 45474 | B36: =YEAR(A36) -> 2024 | C36: =MONTH(A36) -> 7 | D36: ICON | E36: 18934 | F36: 0 | G36: 0 | J36: -0.9913
A37: 45505 | B37: =YEAR(A37) -> 2024 | C37: =MONTH(A37) -> 8 | D37: TANTO | E37: 20568 | F37: 3474 | G37: 4555 | J37: 0.37
A38: 45505 | B38: =YEAR(A38) -> 2024 | C38: =MONTH(A38) -> 8 | D38: SPIL | E38: 11331 | F38: 2640 | G38: 803 | J38: -0.3368
A39: 45505 | B39: =YEAR(A39) -> 2024 | C39: =MONTH(A39) -> 8 | D39: MERATUS | E39: 69 | F39: 527 | G39: 0 | J39: 28.1739
A40: 45505 | B40: =YEAR(A40) -> 2024 | C40: =MONTH(A40) -> 8 | D40: TEMAS | E40: - | F40: 121 | G40: 0 | J40: 0
...

Sheet TOP SERVICES
A1: No. | B1: DATE | C1: YEAR | D1: MONTH | E1: VESSEL OPERATOR | F1: SERVICE | G1: ROUTES | H1: CITY PORT | I1: Service Mode | J1: Total Call | K1: BMPH | L1: GMPH | M1: Average CD | N1: Boxes* | O1: TEUs | P1: ON | Q1: Moves | R1: TEUS | S1: STATUS
A2: 1 | B2: 44562 | C2: =YEAR(B2) -> 2022 | D2: =MONTH(B2) -> 1 | E2: COS | F2: GMI | G2: IDJKT-IDSUB-SGSIN-MYPGU-SGSIN-MYKLA | H2: Jakarta-Surabaya-Singapore-Pasir Gudang-Singapore-Port Kelang West | I2: Feeder | J2: 4 | K2: 37.5425 | L2: 23.34 | M2: 1.68 | N2: 499.75 | O2: 670.75 | P2: 0.5 | Q2: 1999 | R2: 2683 | S2: INTERNATIONAL
A3: 2 | B3: 44563 | C3: =YEAR(B3) -> 2022 | D3: =MONTH(B3) -> 1 | E3: COS | F3: SSS-SAT | G3: SGSIN-IDSUB-SGSIN | H3: Singapore-Surabaya-Singapore | I3: Feeder | J3: 1 | K3: 69.53 | L3: 34.45 | M3: 2.09 | N3: 2041 | O3: 3018 | P3: 1 | Q3: 2041 | R3: 3018 | S3: INTERNATIONAL
A4: 3 | B4: 44564 | C4: =YEAR(B4) -> 2022 | D4: =MONTH(B4) -> 1 | E4: COS | F4: SSS-WED | G4: SGSIN-IDSUB-SGSIN | H4: Singapore-Surabaya-Singapore | I4: Feeder | J4: 1 | K4: 88.67 | L4: 36.55 | M4: 2.63 | N4: 1891 | O4: 2919 | P4: 1 | Q4: 1891 | R4: 2919 | S4: INTERNATIONAL
A5: 4 | B5: 44565 | C5: =YEAR(B5) -> 2022 | D5: =MONTH(B5) -> 1 | E5: GSL | F5: ITS | G5: MYKLA-SGSIN-IDSRG-IDSUB-MYKLA- SGSIN-THBKK THSCS-THLCH | H5: Port Klang-Singapore-Semarang-Surabaya-Port Klang- Singapore-Bangkok Sahathai Terminal-Laem Chabang | I5: Feeder | J5: 1 | K5: 47.24 | L5: 24.88 | M5: 2.08 | N5: 812 | O5: 1184 | P5: 1 | Q5: 812 | R5: 1184 | S5: INTERNATIONAL
A6: 5 | B6: 44566 | C6: =YEAR(B6) -> 2022 | D6: =MONTH(B6) -> 1 | E6: EMC | F6: CIT | G6: CNNBO-CNSGH-HKHKG (Zhujiang)-CNSHK-IDSUB-IDSRG-IDJKT-SGSIN-THLCH-HKHKG-CNNBO | H6: Ningbo-Shanghai-Hong Kong (Zhujiang)-Shekou-Surabaya-Semarang-Jakarta-Singapore-Laemchabang-Hong Kong-Ningbo | I6: Direct | J6: 3 | K6: 54.73667 | L6: 32.47 | M6: 1.69 | N6: 388.3333 | O6: 625.6667 | P6: 0.333333 | Q6: 1165 | R6: 1877 | S6: INTERNATIONAL
A7: 6 | B7: 44567 | C7: =YEAR(B7) -> 2022 | D7: =MONTH(B7) -> 1 | E7: EMC | F7: JPI-A | G7: JPYOK-JPTYO-JPSMZ-JPNGO-JPUKB-TWTPE-TWKHH-PHMNL South-IDSUB-IDJKT-MYTPP-MYBTU-TWKHH | H7: Yokohama-Tokyo-Shimizu-Nagoya-Kobe-Taipei-Kaohsiung-Manila South-Surabaya-Jakarta-Tanjung Pelepas-Bintulu-Kaohsiung | I7: Direct | J7: 4 | K7: 53.41 | L7: 27.5325 | M7: 2.055 | N7: 757.5 | O7: 1179.5 | P7: 1 | Q7: 3030 | R7: 4718 | S7: INTERNATIONAL
A8: 7 | B8: 44568 | C8: =YEAR(B8) -> 2022 | D8: =MONTH(B8) -> 1 | E8: EMC | F8: JPI-B | G8: CNSHK-HKHKG-IDJKT-IDSRG-IDSUB-PHMNL South-TWKHH-TWTPE-JPYOK | H8: Shekou-Hong Kong-Jakarta-Semarang-Surabaya-Manila South-Kaohsiung-Taipei-Yokohama | I8: Direct | J8: 3 | K8: 33.73 | L8: 20.14667 | M8: 1.643333 | N8: 691 | O8: 1076.333 | P8: 0 | Q8: 2073 | R8: 3229 | S8: INTERNATIONAL
A9: 8 | B9: 44569 | C9: =YEAR(B9) -> 2022 | D9: =MONTH(B9) -> 1 | E9: EMC | F9: TMI | G9: IDSUB-IDSRG-MYTPP-THLCH | H9: Surabaya-Semarang-Tanjung Pelepas-Laemchabang | I9: Feeder | J9: 3 | K9: 42.77 | L9: 23.80667 | M9: 1.92 | N9: 521 | O9: 799 | P9: 0 | Q9: 1563 | R9: 2397 | S9: INTERNATIONAL
A10: 9 | B10: 44570 | C10: =YEAR(B10) -> 2022 | D10: =MONTH(B10) -> 1 | E10: EMC | F10: TIS (Discontinue) | G10: - | H10: - | J10: 0 | K10: 0 | L10: 0 | M10: 0 | N10: 0 | O10: 0 | P10: 0 | Q10: 0 | R10: 0 | S10: INTERNATIONAL
A11: 10 | B11: 44571 | C11: =YEAR(B11) -> 2022 | D11: =MONTH(B11) -> 1 | E11: KMT | F11: CKI | G11: KRPUS-KRKWA-CNSGH-CNNBO-HKHKG-IDJKT-IDSUB-VNSGN VNCLI-CNNBO-CNSGH-KRPUS | H11: Pusan-Kwangyang-Shanghai-Ningbo-Hongkong-Jakarta-Surabaya-Hochiminh Cat Lai-Ningbo-Shanghai-Pusan | I11: Direct | J11: 4 | K11: 45.57 | L11: 24.795 | M11: 2.0175 | N11: 692.25 | O11: 1017.5 | P11: 0 | Q11: 2769 | R11: 4070 | S11: INTERNATIONAL
A12: 11 | B12: 44572 | C12: =YEAR(B12) -> 2022 | D12: =MONTH(B12) -> 1 | E12: KAL | F12: Ad Hoc KRL | G12: Various route | H12: Various route | I12: Ad Hoc | J12: 1 | K12: 22.17 | L12: 22.04 | M12: 1.12 | N12: 458 | O12: 458 | P12: 1 | Q12: 458 | R12: 458 | S12: INTERNATIONAL
A13: 12 | B13: 44573 | C13: =YEAR(B13) -> 2022 | D13: =MONTH(B13) -> 1 | E13: MEL | F13: SDS | G13: IDSUB-TLDIL-IDSUB-SGSIN (optional)-IDSUB | H13: Surabaya-Dili-Surabaya-Singapore (optional)-Surabaya | I13: Feeder | J13: 0 | K13: 0 | L13: 0 | M13: 0 | N13: 0 | O13: 0 | P13: 0 | Q13: 0 | R13: 0 | S13: INTERNATIONAL
A14: 13 | B14: 44574 | C14: =YEAR(B14) -> 2022 | D14: =MONTH(B14) -> 1 | E14: KSL | F14: KPG | G14: IDJKT-IDSUB-MYKLA West-INNSA-AEJEA-LKCMB-SADMM-PKKHI-INMUN | H14: Jakarta-Surabaya-Port Klang West-Nhava Sheva-Jebel Ali-Colomba-Dammam-Karachi-Mundra | I14: Direct | J14: 0 | K14: 0 | L14: 0 | M14: 0 | N14: 0 | O14: 0 | P14: 0 | Q14: 0 | R14: 0 | S14: INTERNATIONAL
A15: 14 | B15: 44575 | C15: =YEAR(B15) -> 2022 | D15: =MONTH(B15) -> 1 | E15: MSC | F15: NEW JAVA F | G15: SGSIN-MYTPP-IDJKT-IDSUB-SGSIN | H15: Singapore-Tanjung Pelepas-Jakarta-Surabaya-Singapore | I15: Feeder | J15: 3 | K15: 67 | L15: 28 | M15: 2.4 | N15: 2283 | O15: 3653 | P15: 0.67 | Q15: 6849 | R15: 10960 | S15: INTERNATIONAL
A16: 15 | B16: 44576 | C16: =YEAR(B16) -> 2022 | D16: =MONTH(B16) -> 1 | E16: MSC | F16: NEW JAVA T | G16: SGSIN-MYTPP-IDSRG-IDSUB | H16: Singapore-Tanjung Pelepas-Semarang-Surabaya | I16: Feeder | J16: 1 | K16: 16 | L16: 22 | M16: 1.5 | N16: 286 | O16: 498 | P16: 0 | Q16: 286 | R16: 498 | S16: INTERNATIONAL
A17: 16 | B17: 44577 | C17: =YEAR(B17) -> 2022 | D17: =MONTH(B17) -> 1 | E17: MSC | F17: DOLPHIN | G17: CNSGH-CNNBO-CNXAM-MYTPP-SGSIN-IDJKT-IDSUB-MYTPP-SGSIN-THLCH-VNVUT-CNSGH | H17: Shanghai-Ningbo-Xiamen-Tanjung Pelepas-Singapore-Jakarta-Surabaya-Tanjung Pelepas-Singapore-Laem Chabang-Vung Tau-Shanghai | I17: Direct | J17: 0 | K17: 0 | L17: 0 | M17: 0 | N17: 0 | O17: 0 | P17: 0 | Q17: 0 | R17: 0 | S17: INTERNATIONAL
A18: 17 | B18: 44578 | C18: =YEAR(B18) -> 2022 | D18: =MONTH(B18) -> 1 | E18: MSK | F18: IA-8 | G18: CNSGH-CNTXG-CNQIN-TWKEL-SGSIN-MYTPP-IDJKT-IDSUB-PHDVO-CNSGH | H18: Shanghai-Xingang-Qingdao-Keelung-Singapore-Tanjung Pelepas-Jakarta-Surabaya-Davao-Shanghai | I18: Direct | J18: 4 | K18: 74 | L18: 27 | M18: 2.8 | N18: 2444 | O18: 3929 | P18: 0.5 | Q18: 9776 | R18: 15717 | S18: INTERNATIONAL
A19: 18 | B19: 44579 | C19: =YEAR(B19) -> 2022 | D19: =MONTH(B19) -> 1 | E19: ONE | F19: CS 2 | G19: HKHKG–CNNSH–CNSHK–IDSUB–IDSRG– IDJKT–MYKLA (North)–MYKLA (West)– HKHKG | H19: HongKong–Nansha–Shekou–Surabaya–Semarang– Jakarta–Port Klang (North)–Port Klang (West)– HongKong | I19: Direct | J19: 1 | K19: 33 | L19: 21 | M19: 1.7 | N19: 614 | O19: 948 | P19: 0 | Q19: 614 | R19: 948 | S19: INTERNATIONAL
A20: 19 | B20: 44580 | C20: =YEAR(B20) -> 2022 | D20: =MONTH(B20) -> 1 | E20: OOL | F20: ITS | G20: MYKLA-SGSIN-IDSRG-IDSUB-MYKLA- SGSIN-THBKK THSCS-THLCH | H20: Port Klang-Singapore-Semarang-Surabaya-Port Klang- Singapore-Bangkok Sahathai Terminal-Laem Chabang | I20: Feeder | J20: 2 | K20: 45 | L20: 28 | M20: 1.8 | N20: 710 | O20: 1087 | P20: 0 | Q20: 1420 | R20: 3260 | S20: INTERNATIONAL
A21: 20 | B21: 44581 | C21: =YEAR(B21) -> 2022 | D21: =MONTH(B21) -> 1 | E21: PIL | F21: SSE | G21: SGSIN-IDSUB-SGSIN | H21: Singapore-Surabaya-Singapore | I21: Feeder | J21: 0 | K21: 0 | L21: 0 | M21: 0 | N21: 0 | O21: 0 | P21: 0 | Q21: 0 | R21: 0 | S21: INTERNATIONAL
A22: 21 | B22: 44582 | C22: =YEAR(B22) -> 2022 | D22: =MONTH(B22) -> 1 | E22: PIL | F22: SUS | G22: - | H22: - | I22: - | J22: 0 | K22: 0 | L22: 0 | M22: 0 | N22: 0 | O22: 0 | P22: 0 | Q22: 0 | R22: 0 | S22: INTERNATIONAL
... A44: 43 | B44: 44600 | C44: =YEAR(B44) -> 2022 | D44: =MONTH(B44) -> 2 | E44: EMC | F44: TMI | G44: IDSUB-IDSRG-MYTPP-THLCH | H44: Surabaya-Semarang-Tanjung Pelepas-Laemchabang | I44: Feeder | J44: 4 | K44: 39 | L44: 21 | M44: 2 | N44: 473 | O44: 751 | P44: 0.5 | Q44: 1892 | R44: 3003 | S44: INTERNATIONAL
A45: 44 | B45: 44601 | C45: =YEAR(B45) -> 2022 | D45: =MONTH(B45) -> 2 | E45: EMC | F45: TIS (Discontinue) | G45: - | H45: - | J45: 0 | K45: 0 | L45: 0 | M45: 0 | N45: 0 | O45: 0 | P45: 0 | Q45: 0 | R45: 0 | S45: INTERNATIONAL
A46: 45 | B46: 44602 | C46: =YEAR(B46) -> 2022 | D46: =MONTH(B46) -> 2 | E46: KMT | F46: CKI | G46: KRPUS-KRKWA-CNSGH-CNNBO-HKHKG-IDJKT-IDSUB-VNSGN VNCLI-CNNBO-CNSGH-KRPUS | H46: Pusan-Kwangyang-Shanghai-Ningbo-Hongkong-Jakarta-Surabaya-Hochiminh Cat Lai-Ningbo-Shanghai-Pusan | I46: Direct | J46: 3 | K46: 35 | L46: 19 | M46: 1.8 | N46: 654 | O46: 944 | P46: 0.67 | Q46: 1961 | R46: 2831 | S46: INTERNATIONAL
A47: 46 | B47: 44603 | C47: =YEAR(B47) -> 2022 | D47: =MONTH(B47) -> 2 | E47: KAL | F47: Ad Hoc KRL | G47: Various route | H47: Various route | I47: Ad Hoc | J47: 0 | K47: 0 | L47: 0 | M47: 0 | N47: 0 | O47: 0 | P47: 0 | Q47: 0 | R47: 0 | S47: INTERNATIONAL
A48: 47 | B48: 44604 | C48: =YEAR(B48) -> 2022 | D48: =MONTH(B48) -> 2 | E48: MEL | F48: SDS | G48: IDSUB-TLDIL-IDSUB-SGSIN (optional)-IDSUB | H48: Surabaya-Dili-Surabaya-Singapore (optional)-Surabaya | I48: Feeder | J48: 0 | K48: 0 | L48: 0 | M48: 0 | N48: 0 | O48: 0 | P48: 0 | Q48: 0 | R48: 0 | S48: INTERNATIONAL
A49: 48 | B49: 44605 | C49: =YEAR(B49) -> 2022 | D49: =MONTH(B49) -> 2 | E49: KSL | F49: KPG | G49: IDJKT-IDSUB-MYKLA West-INNSA-AEJEA-LKCMB-SADMM-PKKHI-INMUN | H49: Jakarta-Surabaya-Port Klang West-Nhava Sheva-Jebel Ali-Colomba-Dammam-Karachi-Mundra | I49: Direct | J49: 0 | K49: 0 | L49: 0 | M49: 0 | N49: 0 | O49: 0 | P49: 0 | Q49: 0 | R49: 0 | S49: INTERNATIONAL
A50: 49 | B50: 44606 | C50: =YEAR(B50) -> 2022 | D50: =MONTH(B50) -> 2 | E50: MSC | F50: NEW JAVA F | G50: SGSIN-MYTPP-IDJKT-IDSUB-SGSIN | H50: Singapore-Tanjung Pelepas-Jakarta-Surabaya-Singapore | I50: Feeder | J50: 3 | K50: 59 | L50: 26 | M50: 2.4 | N50: 1766 | O50: 2741 | P50: 0.33 | Q50: 5297 | R50: 8222 | S50: INTERNATIONAL
A51: 50 | B51: 44607 | C51: =YEAR(B51) -> 2022 | D51: =MONTH(B51) -> 2 | E51: MSC | F51: NEW JAVA T | G51: SGSIN-MYTPP-IDSRG-IDSUB | H51: Singapore-Tanjung Pelepas-Semarang-Surabaya | I51: Feeder | J51: 1 | K51: 51 | L51: 24 | M51: 2.3 | N51: 1454 | O51: 2262 | P51: 0 | Q51: 1454 | R51: 2262 | S51: INTERNATIONAL
A52: 51 | B52: 44608 | C52: =YEAR(B52) -> 2022 | D52: =MONTH(B52) -> 2 | E52: MSC | F52: DOLPHIN | G52: CNSGH-CNNBO-CNXAM-MYTPP-SGSIN-IDJKT-IDSUB-MYTPP-SGSIN-THLCH-VNVUT-CNSGH | H52: Shanghai-Ningbo-Xiamen-Tanjung Pelepas-Singapore-Jakarta-Surabaya-Tanjung Pelepas-Singapore-Laem Chabang-Vung Tau-Shanghai | I52: Direct | J52: 0 | K52: 0 | L52: 0 | M52: 0 | N52: 0 | O52: 0 | P52: 0 | Q52: 0 | R52: 0 | S52: INTERNATIONAL
A53: 52 | B53: 44609 | C53: =YEAR(B53) -> 2022 | D53: =MONTH(B53) -> 2 | E53: MSK | F53: IA-8 | G53: CNSGH-CNTXG-CNQIN-TWKEL-SGSIN-MYTPP-IDJKT-IDSUB-PHDVO-CNSGH | H53: Shanghai-Xingang-Qingdao-Keelung-Singapore-Tanjung Pelepas-Jakarta-Surabaya-Davao-Shanghai | I53: Direct | J53: 4 | K53: 61 | L53: 25 | M53: 2.4 | N53: 2430 | O53: 3780 | P53: 0.25 | Q53: 9719 | R53: 15119 | S53: INTERNATIONAL
A54: 53 | B54: 44610 | C54: =YEAR(B54) -> 2022 | D54: =MONTH(B54) -> 2 | E54: ONE | F54: CS 2 | G54: HKHKG–CNNSH–CNSHK–IDSUB–IDSRG– IDJKT–MYKLA (North)–MYKLA (West)– HKHKG | H54: HongKong–Nansha–Shekou–Surabaya–Semarang– Jakarta–Port Klang (North)–Port Klang (West)– HongKong | I54: Direct | J54: 2 | K54: 32 | L54: 24 | M54: 1.6 | N54: 651 | O54: 1022 | P54: 0 | Q54: 1302 | R54: 2044 | S54: INTERNATIONAL
A55: 54 | B55: 44611 | C55: =YEAR(B55) -> 2022 | D55: =MONTH(B55) -> 2 | E55: OOL | F55: ITS | G55: MYKLA-SGSIN-IDSRG-IDSUB-MYKLA- SGSIN-THBKK THSCS-THLCH | H55: Port Klang-Singapore-Semarang-Surabaya-Port Klang- Singapore-Bangkok Sahathai Terminal-Laem Chabang | I55: Feeder | J55: 1 | K55: 33 | L55: 15 | M55: 2 | N55: 710 | O55: 1120 | P55: 0 | Q55: 710 | R55: 2240 | S55: INTERNATIONAL
A56: 55 | B56: 44612 | C56: =YEAR(B56) -> 2022 | D56: =MONTH(B56) -> 2 | E56: PIL | F56: SSE | G56: SGSIN-IDSUB-SGSIN | H56: Singapore-Surabaya-Singapore | I56: Feeder | J56: 0 | K56: 0 | L56: 0 | M56: 0 | N56: 0 | O56: 0 | P56: 0 | Q56: 0 | R56: 0 | S56: INTERNATIONAL
A57: 56 | B57: 44613 | C57: =YEAR(B57) -> 2022 | D57: =MONTH(B57) -> 2 | E57: PIL | F57: SUS | G57: - | H57: - | I57: - | J57: 0 | K57: 0 | L57: 0 | M57: 0 | N57: 0 | O57: 0 | P57: 0 | Q57: 0 | R57: 0 | S57: INTERNATIONAL
... A79: 78 | B79: 44628 | C79: =YEAR(B79) -> 2022 | D79: =MONTH(B79) -> 3 | E79: EMC | F79: TMI | G79: IDSUB-IDSRG-MYTPP-THLCH | H79: Surabaya-Semarang-Tanjung Pelepas-Laemchabang | I79: Feeder | J79: 1 | K79: 49 | L79: 28 | M79: 2 | N79: 505 | O79: 778 | P79: 0 | Q79: 505 | R79: 778 | S79: INTERNATIONAL
A80: 79 | B80: 44629 | C80: =YEAR(B80) -> 2022 | D80: =MONTH(B80) -> 3 | E80: EMC | F80: TIS (Discontinue) | G80: - | H80: - | J80: 0 | K80: 0 | L80: 0 | M80: 0 | N80: 0 | O80: 0 | P80: 0 | Q80: 0 | R80: 0 | S80: INTERNATIONAL
A81: 80 | B81: 44630 | C81: =YEAR(B81) -> 2022 | D81: =MONTH(B81) -> 3 | E81: KMT | F81: CKI | G81: KRPUS-KRKWA-CNSGH-CNNBO-HKHKG-IDJKT-IDSUB-VNSGN VNCLI-CNNBO-CNSGH-KRPUS | H81: Pusan-Kwangyang-Shanghai-Ningbo-Hongkong-Jakarta-Surabaya-Hochiminh Cat Lai-Ningbo-Shanghai-Pusan | I81: Direct | K81: 4 | L81: 39 | M81: 21 | N81: 2 | O81: 695 | P81: 969 | Q81: 0.25 | R81: 2781 | S81: INTERNATIONAL
A82: 81 | B82: 44631 | C82: =YEAR(B82) -> 2022 | D82: =MONTH(B82) -> 3 | E82: KAL | F82: Ad Hoc KRL | G82: Various route | H82: Various route | I82: Ad Hoc | J82: 1 | K82: 26 | L82: 21 | M82: 1.4 | N82: 316 | O82: 317 | P82: 1 | Q82: 316 | R82: 317 | S82: INTERNATIONAL
...

Sheet SL DOM
A1: TANGGAL | B1: YEAR | C1: MONTH | D1: LOP | E1: TEUS
A2: 44562 | B2: =YEAR(A2) -> 2022 | C2: =MONTH(A2) -> 1 | D2: TANTO INTIM LINE | E2: 3232
A3: 44563 | B3: =YEAR(A3) -> 2022 | C3: =MONTH(A3) -> 1 | D3: SALAM PACIFIC LINE | E3: 2438
A4: 44564 | B4: =YEAR(A4) -> 2022 | C4: =MONTH(A4) -> 1 | D4: MERATUS | E4: 0
A5: 44565 | B5: =YEAR(A5) -> 2022 | C5: =MONTH(A5) -> 1 | D5: TEMAS | E5: 0
A6: 44566 | B6: =YEAR(A6) -> 2022 | C6: =MONTH(A6) -> 1 | D6: ICON LINE | E6: 2543
A7: 44593 | B7: =YEAR(A7) -> 2022 | C7: =MONTH(A7) -> 2 | D7: TANTO INTIM LINE | E7: 4185
A8: 44594 | B8: =YEAR(A8) -> 2022 | C8: =MONTH(A8) -> 2 | D8: SALAM PACIFIC LINE | E8: 4171
A9: 44595 | B9: =YEAR(A9) -> 2022 | C9: =MONTH(A9) -> 2 | D9: MERATUS | E9: 0
A10: 44596 | B10: =YEAR(A10) -> 2022 | C10: =MONTH(A10) -> 2 | D10: TEMAS | E10: 0
